Traceback (most recent call last):
  File "/usr/local/lib/python3.9/dist-packages/jupyter_cache/executors/utils.py", line 58, in single_nb_execution
    executenb(
  File "/usr/local/lib/python3.9/dist-packages/nbclient/client.py", line 1204, in execute
    return NotebookClient(nb=nb, resources=resources, km=km, **kwargs).execute()
  File "/usr/local/lib/python3.9/dist-packages/nbclient/util.py", line 84, in wrapped
    return just_run(coro(*args, **kwargs))
  File "/usr/local/lib/python3.9/dist-packages/nbclient/util.py", line 62, in just_run
    return loop.run_until_complete(coro)
  File "/usr/lib/python3.9/asyncio/base_events.py", line 647, in run_until_complete
    return future.result()
  File "/usr/local/lib/python3.9/dist-packages/nbclient/client.py", line 663, in async_execute
    await self.async_execute_cell(
  File "/usr/local/lib/python3.9/dist-packages/nbclient/client.py", line 965, in async_execute_cell
    await self._check_raise_for_error(cell, cell_index, exec_reply)
  File "/usr/local/lib/python3.9/dist-packages/nbclient/client.py", line 862, in _check_raise_for_error
    raise CellExecutionError.from_cell_and_msg(cell, exec_reply_content)
nbclient.exceptions.CellExecutionError: An error occurred while executing the following cell:
------------------
#Check Accuracy precision, recall, f1-score
print( classification_report(Y_test, knn.predict(X_test_scaled)) )
#Another way to get the models accuracy on the test data
print(F'Accuracy:',accuracy_score(Y_test, knn.predict(X_test_scaled)))
print(F'Precision:', precision_score(Y_test, knn.predict(X_test_scaled)))
print(F'Recall:', recall_score(Y_test, knn.predict(X_test_scaled)))
print(F'F1 Score:', f1_score(Y_test, knn.predict(X_test_scaled)))

#Check Roc Auc Score
print( F'Roc Auc Score:',roc_auc_score(Y_test, knn.predict(X_test_scaled)) )

print( F'Balanced Accuracy Score:',balanced_accuracy_score(y_test, knn.predict(X_test_scaled)) ) 
print( F'Confusion Matrix:',confusion_matrix(Y_test, knn.predict(X_test_scaled)) )
print()#Print a new line
------------------

[0;31m[0m
[0;31mNameError[0mTraceback (most recent call last)
[0;32m<ipython-input-13-77bd1a066985>[0m in [0;36m<cell line: 2>[0;34m()[0m
[1;32m      1[0m [0;31m#Check Accuracy precision, recall, f1-score[0m[0;34m[0m[0;34m[0m[0m
[0;32m----> 2[0;31m [0mprint[0m[0;34m([0m [0mclassification_report[0m[0;34m([0m[0mY_test[0m[0;34m,[0m [0mknn[0m[0;34m.[0m[0mpredict[0m[0;34m([0m[0mX_test_scaled[0m[0;34m)[0m[0;34m)[0m [0;34m)[0m[0;34m[0m[0;34m[0m[0m
[0m[1;32m      3[0m [0;31m#Another way to get the models accuracy on the test data[0m[0;34m[0m[0;34m[0m[0m
[1;32m      4[0m [0mprint[0m[0;34m([0m[0;34mF'Accuracy:'[0m[0;34m,[0m[0maccuracy_score[0m[0;34m([0m[0mY_test[0m[0;34m,[0m [0mknn[0m[0;34m.[0m[0mpredict[0m[0;34m([0m[0mX_test_scaled[0m[0;34m)[0m[0;34m)[0m[0;34m)[0m[0;34m[0m[0;34m[0m[0m
[1;32m      5[0m [0mprint[0m[0;34m([0m[0;34mF'Precision:'[0m[0;34m,[0m [0mprecision_score[0m[0;34m([0m[0mY_test[0m[0;34m,[0m [0mknn[0m[0;34m.[0m[0mpredict[0m[0;34m([0m[0mX_test_scaled[0m[0;34m)[0m[0;34m)[0m[0;34m)[0m[0;34m[0m[0;34m[0m[0m

[0;31mNameError[0m: name 'classification_report' is not defined
NameError: name 'classification_report' is not defined

